<mujoco model="door_scene">
    <option gravity="0 0 -9.81" />
    <compiler angle="radian" />

    <worldbody>

        <body name="door" pos="0 0 0" quat="1 0 0 0">
            <freejoint name="door_root" />

            <geom name="wall_geom_right" type="box" size="0.05 0.5 1.025" pos="0 -1.1 1.025"
                rgba="0.6 0.6 0.6 1"
                contype="2" conaffinity="1"/>
            <geom name="wall_geom_left" type="box" size="0.05 0.5 1.025" pos="0 1.1 1.025"
                rgba="0.6 0.6 0.6 1"
                contype="2" conaffinity="1"/>
            <!-- <geom name="wall_geom_bottom" type="box" size="0.05 0.5 0.025" pos="0 0 0.025"
                rgba="0.6 0.6 0.6 1"
                contype="2" conaffinity="1" mass="10" /> -->

            <body name="door_panel" pos="0 0 0">
                <joint name="door_joint" type="hinge" pos="0 0.5 0" axis="0 0 1" range="-1.57 0" stiffness="0" damping="1" springref="0" />
                <geom name="door_geom" type="box" size="0.02 0.5 0.975" pos="0 0 1" rgba="0.4 0.3 0.1 1.0" contype="2" conaffinity="1" mass="20" />
            </body>
        </body>
    </worldbody>

</mujoco>